<robot name = "robot">
    <link name="Cube0">
        <inertial>
            <origin xyz="0 0 1" rpy="0 0 0"/>
            <mass value="1" />
            <inertia ixx="100" ixy="0" ixz="0" iyy="100" iyz="0" izz="100" />
        </inertial>
        <visual>
            <origin xyz="0 0 1" rpy="0 0 0"/>
            <geometry>
                <box size="1 1 1" />
            </geometry>
            <material name="Green">
                <color rgba="0 1.0 0.0 1.0"/>
            </material>
        </visual>
        <collision>
            <origin xyz="0 0 1" rpy="0 0 0"/>
            <geometry>
                <box size="1 1 1" />
            </geometry>
        </collision>
    </link>
    <joint name="Cube0_Cube1" type="revolute">
       <parent link="Cube0"/>
       <child  link="Cube1"/>
       <origin rpy="0 0 0" xyz="0 0.5 1" />
     <axis xyz="1 0 1"/>
       <limit effort="0.0" lower="-3.14159" upper="3.14159" velocity="0.0"/>
    </joint>
    <link name="Cube1">
        <inertial>
            <origin xyz="0 0.5 0" rpy="0 0 0"/>
            <mass value="1" />
            <inertia ixx="100" ixy="0" ixz="0" iyy="100" iyz="0" izz="100" />
        </inertial>
        <visual>
            <origin xyz="0 0.5 0" rpy="0 0 0"/>
            <geometry>
                <box size="1 1 1" />
            </geometry>
            <material name="Green">
                <color rgba="0 1.0 0.0 1.0"/>
            </material>
        </visual>
        <collision>
            <origin xyz="0 0.5 0" rpy="0 0 0"/>
            <geometry>
                <box size="1 1 1" />
            </geometry>
        </collision>
    </link>
    <link name="Cube2">
        <inertial>
            <origin xyz="0 0.6203632271362195 0" rpy="0 0 0"/>
            <mass value="1" />
            <inertia ixx="100" ixy="0" ixz="0" iyy="100" iyz="0" izz="100" />
        </inertial>
        <visual>
            <origin xyz="0 0.6203632271362195 0" rpy="0 0 0"/>
            <geometry>
                <box size="1.2987677023572899 1.240726454272439 0.7112730979612141" />
            </geometry>
            <material name="Cyan">
                <color rgba="0 1.0 1.0 1.0"/>
            </material>
        </visual>
        <collision>
            <origin xyz="0 0.6203632271362195 0" rpy="0 0 0"/>
            <geometry>
                <box size="1.2987677023572899 1.240726454272439 0.7112730979612141" />
            </geometry>
        </collision>
    </link>
    <joint name="Cube1_Cube2" type="revolute">
       <parent link="Cube1"/>
       <child  link="Cube2"/>
       <origin rpy="0 0 0" xyz="0 1.1 0" />
     <axis xyz="1 0 1"/>
       <limit effort="0.0" lower="-3.14159" upper="3.14159" velocity="0.0"/>
    </joint>
    <link name="Cube3">
        <inertial>
            <origin xyz="0 0.45916437936981813 0" rpy="0 0 0"/>
            <mass value="1" />
            <inertia ixx="100" ixy="0" ixz="0" iyy="100" iyz="0" izz="100" />
        </inertial>
        <visual>
            <origin xyz="0 0.45916437936981813 0" rpy="0 0 0"/>
            <geometry>
                <box size="0.8010418801224821 0.9183287587396363 0.31871570975598135" />
            </geometry>
            <material name="Cyan">
                <color rgba="0 1.0 1.0 1.0"/>
            </material>
        </visual>
        <collision>
            <origin xyz="0 0.45916437936981813 0" rpy="0 0 0"/>
            <geometry>
                <box size="0.8010418801224821 0.9183287587396363 0.31871570975598135" />
            </geometry>
        </collision>
    </link>
    <joint name="Cube2_Cube3" type="revolute">
       <parent link="Cube2"/>
       <child  link="Cube3"/>
       <origin rpy="0 0 0" xyz="0 1.340726454272439 0" />
     <axis xyz="1 0 1"/>
       <limit effort="0.0" lower="-3.14159" upper="3.14159" velocity="0.0"/>
    </joint>
    <link name="Cube4">
        <inertial>
            <origin xyz="0 0.5713211596937323 0" rpy="0 0 0"/>
            <mass value="1" />
            <inertia ixx="100" ixy="0" ixz="0" iyy="100" iyz="0" izz="100" />
        </inertial>
        <visual>
            <origin xyz="0 0.5713211596937323 0" rpy="0 0 0"/>
            <geometry>
                <box size="0.9973186136484216 1.1426423193874646 1.1511879738988233" />
            </geometry>
            <material name="Cyan">
                <color rgba="0 1.0 1.0 1.0"/>
            </material>
        </visual>
        <collision>
            <origin xyz="0 0.5713211596937323 0" rpy="0 0 0"/>
            <geometry>
                <box size="0.9973186136484216 1.1426423193874646 1.1511879738988233" />
            </geometry>
        </collision>
    </link>
    <joint name="Cube3_Cube4" type="revolute">
       <parent link="Cube3"/>
       <child  link="Cube4"/>
       <origin rpy="0 0 0" xyz="0 1.0183287587396364 0" />
     <axis xyz="1 0 1"/>
       <limit effort="0.0" lower="-3.14159" upper="3.14159" velocity="0.0"/>
    </joint>
    <link name="Cube5">
        <inertial>
            <origin xyz="0 0.2115802309430523 0" rpy="0 0 0"/>
            <mass value="1" />
            <inertia ixx="100" ixy="0" ixz="0" iyy="100" iyz="0" izz="100" />
        </inertial>
        <visual>
            <origin xyz="0 0.2115802309430523 0" rpy="0 0 0"/>
            <geometry>
                <box size="1.1473205875042873 0.4231604618861046 0.43741640046826585" />
            </geometry>
            <material name="Green">
                <color rgba="0 1.0 0.0 1.0"/>
            </material>
        </visual>
        <collision>
            <origin xyz="0 0.2115802309430523 0" rpy="0 0 0"/>
            <geometry>
                <box size="1.1473205875042873 0.4231604618861046 0.43741640046826585" />
            </geometry>
        </collision>
    </link>
    <joint name="Cube4_Cube5" type="revolute">
       <parent link="Cube4"/>
       <child  link="Cube5"/>
       <origin rpy="0 0 0" xyz="0 1.2426423193874647 0" />
     <axis xyz="1 0 1"/>
       <limit effort="0.0" lower="-3.14159" upper="3.14159" velocity="0.0"/>
    </joint>
    <link name="Cube6">
        <inertial>
            <origin xyz="0 0.20817255800531206 0" rpy="0 0 0"/>
            <mass value="1" />
            <inertia ixx="100" ixy="0" ixz="0" iyy="100" iyz="0" izz="100" />
        </inertial>
        <visual>
            <origin xyz="0 0.20817255800531206 0" rpy="0 0 0"/>
            <geometry>
                <box size="1.2578273840169725 0.41634511601062413 0.6515129614460291" />
            </geometry>
            <material name="Green">
                <color rgba="0 1.0 0.0 1.0"/>
            </material>
        </visual>
        <collision>
            <origin xyz="0 0.20817255800531206 0" rpy="0 0 0"/>
            <geometry>
                <box size="1.2578273840169725 0.41634511601062413 0.6515129614460291" />
            </geometry>
        </collision>
    </link>
    <joint name="Cube5_Cube6" type="revolute">
       <parent link="Cube5"/>
       <child  link="Cube6"/>
       <origin rpy="0 0 0" xyz="0 0.5231604618861047 0" />
     <axis xyz="1 0 1"/>
       <limit effort="0.0" lower="-3.14159" upper="3.14159" velocity="0.0"/>
    </joint>
    <link name="Cube7">
        <inertial>
            <origin xyz="0 0.18702881295562832 0" rpy="0 0 0"/>
            <mass value="1" />
            <inertia ixx="100" ixy="0" ixz="0" iyy="100" iyz="0" izz="100" />
        </inertial>
        <visual>
            <origin xyz="0 0.18702881295562832 0" rpy="0 0 0"/>
            <geometry>
                <box size="1.1841134522953773 0.37405762591125663 0.9423598266097608" />
            </geometry>
            <material name="Cyan">
                <color rgba="0 1.0 1.0 1.0"/>
            </material>
        </visual>
        <collision>
            <origin xyz="0 0.18702881295562832 0" rpy="0 0 0"/>
            <geometry>
                <box size="1.1841134522953773 0.37405762591125663 0.9423598266097608" />
            </geometry>
        </collision>
    </link>
    <joint name="Cube6_Cube7" type="revolute">
       <parent link="Cube6"/>
       <child  link="Cube7"/>
       <origin rpy="0 0 0" xyz="0 0.5163451160106242 0" />
     <axis xyz="1 0 1"/>
       <limit effort="0.0" lower="-3.14159" upper="3.14159" velocity="0.0"/>
    </joint>
</robot>